<?xml version="1.0" encoding="utf-8" ?>
<!-- This URDF was automatically created by SolidWorks to URDF Exporter! Originally created by Stephen Brawner (brawner@gmail.com) 
     Commit Version: 1.6.0-1-g15f4949  Build Version: 1.6.7594.29634
     For more information, please see http://wiki.ros.org/sw_urdf_exporter -->
<robot name="rod">
    <link name="world" />
    <joint name="world_fixed" type="fixed">
        <parent link="world" />
        <child link="base_link" />
    </joint>
    <link name="base_link">
        <inertial>
            <origin xyz="0.0762 0.0762 0.005" rpy="0 0 0" />
            <mass value="0.23126" />
            <inertia ixx="0.00045145" ixy="3.0552E-21" ixz="4.3368E-25" iyy="0.00045145" iyz="-1.205E-21" izz="0.00089904" />
        </inertial>
        <visual>
            <origin xyz="0 0 0" rpy="0 0 0" />
            <geometry>
                <mesh filename="package://rod/meshes/base_link.STL" />
            </geometry>
            <material name="">
                <color rgba="0.79216 0.81961 0.93333 1" />
            </material>
        </visual>
        <collision>
            <origin xyz="0 0 0" rpy="0 0 0" />
            <geometry>
                <mesh filename="package://rod/meshes/base_link.STL" />
            </geometry>
        </collision>
    </link>
    <link name="link1">
        <inertial>
            <origin xyz="0.0049588 0.005 0.15362" rpy="0 0 0" />
            <mass value="0.03048" />
            <inertia ixx="0.00023618" ixy="-6.6722E-24" ixz="1.837E-07" iyy="0.0002362" iyz="-3.1176E-20" izz="5.2051E-07" />
        </inertial>
        <visual>
            <origin xyz="0 0 0" rpy="0 0 0" />
            <geometry>
                <mesh filename="package://rod/meshes/link1.STL" />
            </geometry>
            <material name="">
                <color rgba="0.79216 0.81961 0.93333 1" />
            </material>
        </visual>
        <collision>
            <origin xyz="0 0 0" rpy="0 0 0" />
            <geometry>
                <mesh filename="package://rod/meshes/link1.STL" />
            </geometry>
        </collision>
    </link>
    <joint name="joint1" type="fixed">
        <origin xyz="0.0712 0.0712 0" rpy="0 0 0" />
        <parent link="base_link" />
        <child link="link1" />
        <axis xyz="0 0 0" />
    </joint>
    <link name="link2">
        <inertial>
            <origin xyz="-0.0050412 0.14398 0.03682" rpy="0 0 0" />
            <mass value="0.03048" />
            <inertia ixx="0.00023618" ixy="1.7797E-07" ixz="4.5513E-08" iyy="1.4987E-05" iyz="-5.6569E-05" izz="0.00022173" />
        </inertial>
        <visual>
            <origin xyz="0 0 0" rpy="0 0 0" />
            <geometry>
                <mesh filename="package://rod/meshes/link2.STL" />
            </geometry>
            <material name="">
                <color rgba="0.79216 0.81961 0.93333 1" />
            </material>
        </visual>
        <collision>
            <origin xyz="0 0 0" rpy="0 0 0" />
            <geometry>
                <mesh filename="package://rod/meshes/link2.STL" />
            </geometry>
        </collision>
    </link>
    <joint name="joint2" type="revolute">
        <origin xyz="0 0.005 0.2998" rpy="0 0 0" />
        <parent link="link1" />
        <child link="link2" />
        <axis xyz="1 0 0" />
        <limit lower="0" upper="3.14159" effort="10" velocity="3" />
    </joint>
    <transmission name="trans_joint2">
        <type>transmission_interface/SimpleTransmission</type>
        <joint name="joint2">
            <hardwareInterface>hardware_interface/PositionJointInterface</hardwareInterface>
        </joint>
        <actuator name="joint2_motor">
            <hardwareInterface>hardware_interface/PositionJointInterface</hardwareInterface>
            <mechanicalReduction>1</mechanicalReduction>
        </actuator>
    </transmission>
    <gazebo>
        <plugin name="gazebo_ros_control" filename= "libgazebo_ros_control.so">
            <robotNamespace>/</robotNamespace>
        </plugin>
    </gazebo>
</robot>

